D:\py-prj\chatbotv1\venv\lib\site-packages\rasa\core\tracker_store.py:1044: MovedIn20Warning: The ``declarative_base()`` function is now available as sqlalchemy.orm.declarative_base(). (deprecated since: 2.0) (Background on SQLAlchemy 2.0 at: https://sqlalche.me/e/b8d9)
  Base: DeclarativeMeta = declarative_base()
D:\py-prj\chatbotv1\venv\lib\site-packages\rasa\shared\utils\validation.py:134: DeprecationWarning: pkg_resources is deprecated as an API. See https://setuptools.pypa.io/en/latest/pkg_resources.html
  import pkg_resources
D:\py-prj\chatbotv1\venv\lib\site-packages\pkg_resources\__init__.py:3117: DeprecationWarning: Deprecated call to `pkg_resources.declare_namespace('mpl_toolkits')`.
Implementing implicit namespace packages (as specified in PEP 420) is preferred to `pkg_resources.declare_namespace`. See https://setuptools.pypa.io/en/latest/references/keywords.html#keyword-namespace-packages
  declare_namespace(pkg)
D:\py-prj\chatbotv1\venv\lib\site-packages\pkg_resources\__init__.py:3117: DeprecationWarning: Deprecated call to `pkg_resources.declare_namespace('ruamel')`.
Implementing implicit namespace packages (as specified in PEP 420) is preferred to `pkg_resources.declare_namespace`. See https://setuptools.pypa.io/en/latest/references/keywords.html#keyword-namespace-packages
  declare_namespace(pkg)
D:\py-prj\chatbotv1\venv\lib\site-packages\sanic_cors\extension.py:39: DeprecationWarning: distutils Version classes are deprecated. Use packaging.version instead.
  SANIC_VERSION = LooseVersion(sanic_version)
D:\py-prj\chatbotv1\venv\lib\site-packages\tensorflow\lite\python\util.py:52: DeprecationWarning: jax.xla_computation is deprecated. Please use the AOT APIs.
  from jax import xla_computation as _xla_computation
2025-04-18 07:12:51 [1;30mINFO    [0m [34mroot[0m  - Starting Rasa server on http://0.0.0.0:5005
2025-04-18 07:12:52 [1;30mINFO    [0m [34mrasa.core.processor[0m  - Loading model models\20250418-071056-complicated-supernova.tar.gz...
2025-04-18 07:13:22 [1;30mWARNING [0m [34mrasa.shared.utils.common[0m  - [33mThe UnexpecTED Intent Policy is currently experimental and might change or be removed in the future \U0001f52c Please share your feedback on it in the forum (https://forum.rasa.com) to help us make this feature ready for production.[0m
2025-04-18 07:13:38 [1;30mINFO    [0m [34mroot[0m  - Rasa server is up and running.
2025-04-18 07:15:07 [1;30mERROR   [0m [34mrasa.core.actions.action[0m  - [31mFailed to run custom action 'action_get_informasi'. Couldn't connect to the server at 'http://localhost:5055/webhook'. Is the server running? Error: Cannot connect to host localhost:5055 ssl:default [The remote computer refused the network connection][0m
2025-04-18 07:15:07 [1;30mERROR   [0m [34mrasa.core.processor[0m  - [31mEncountered an exception while running action 'action_get_informasi'.Bot will continue, but the actions events are lost. Please check the logs of your action server for more information.[0m
Traceback (most recent call last):
  File "D:\py-prj\chatbotv1\venv\lib\site-packages\aiohttp\connector.py", line 1025, in _wrap_create_connection
    return await self._loop.create_connection(*args, **kwargs)
  File "C:\Program Files\WindowsApps\PythonSoftwareFoundation.Python.3.10_3.10.3056.0_x64__qbz5n2kfra8p0\lib\asyncio\base_events.py", line 1076, in create_connection
    raise exceptions[0]
  File "C:\Program Files\WindowsApps\PythonSoftwareFoundation.Python.3.10_3.10.3056.0_x64__qbz5n2kfra8p0\lib\asyncio\base_events.py", line 1060, in create_connection
    sock = await self._connect_sock(
  File "C:\Program Files\WindowsApps\PythonSoftwareFoundation.Python.3.10_3.10.3056.0_x64__qbz5n2kfra8p0\lib\asyncio\base_events.py", line 969, in _connect_sock
    await self.sock_connect(sock, address)
  File "C:\Program Files\WindowsApps\PythonSoftwareFoundation.Python.3.10_3.10.3056.0_x64__qbz5n2kfra8p0\lib\asyncio\proactor_events.py", line 709, in sock_connect
    return await self._proactor.connect(sock, address)
  File "C:\Program Files\WindowsApps\PythonSoftwareFoundation.Python.3.10_3.10.3056.0_x64__qbz5n2kfra8p0\lib\asyncio\windows_events.py", line 826, in _poll
    value = callback(transferred, key, ov)
  File "C:\Program Files\WindowsApps\PythonSoftwareFoundation.Python.3.10_3.10.3056.0_x64__qbz5n2kfra8p0\lib\asyncio\windows_events.py", line 613, in finish_connect
    ov.getresult()
ConnectionRefusedError: [WinError 1225] The remote computer refused the network connection

The above exception was the direct cause of the following exception:

Traceback (most recent call last):
  File "D:\py-prj\chatbotv1\venv\lib\site-packages\rasa\core\actions\action.py", line 780, in run
    response: Any = await self.action_endpoint.request(
  File "D:\py-prj\chatbotv1\venv\lib\site-packages\rasa\utils\endpoints.py", line 174, in request
    async with session.request(
  File "D:\py-prj\chatbotv1\venv\lib\site-packages\aiohttp\client.py", line 1197, in __aenter__
    self._resp = await self._coro
  File "D:\py-prj\chatbotv1\venv\lib\site-packages\aiohttp\client.py", line 581, in _request
    conn = await self._connector.connect(
  File "D:\py-prj\chatbotv1\venv\lib\site-packages\aiohttp\connector.py", line 544, in connect
    proto = await self._create_connection(req, traces, timeout)
  File "D:\py-prj\chatbotv1\venv\lib\site-packages\aiohttp\connector.py", line 944, in _create_connection
    _, proto = await self._create_direct_connection(req, traces, timeout)
  File "D:\py-prj\chatbotv1\venv\lib\site-packages\aiohttp\connector.py", line 1257, in _create_direct_connection
    raise last_exc
  File "D:\py-prj\chatbotv1\venv\lib\site-packages\aiohttp\connector.py", line 1226, in _create_direct_connection
    transp, proto = await self._wrap_create_connection(
  File "D:\py-prj\chatbotv1\venv\lib\site-packages\aiohttp\connector.py", line 1033, in _wrap_create_connection
    raise client_error(req.connection_key, exc) from exc
aiohttp.client_exceptions.ClientConnectorError: Cannot connect to host localhost:5055 ssl:default [The remote computer refused the network connection]

During handling of the above exception, another exception occurred:

Traceback (most recent call last):
  File "D:\py-prj\chatbotv1\venv\lib\site-packages\rasa\core\processor.py", line 982, in _run_action
    events = await action.run(
  File "D:\py-prj\chatbotv1\venv\lib\site-packages\rasa\core\actions\action.py", line 821, in run
    raise RasaException(
rasa.shared.exceptions.RasaException: Failed to execute custom action 'action_get_informasi'. Couldn't connect to the server at 'http://localhost:5055/webhook.
